<?xml version="1.0" ?>
<!-- =================================================================================== -->
<!-- |    This document was autogenerated by xacro from giraffe.urdf.xacro             | -->
<!-- |    EDITING THIS FILE BY HAND IS NOT RECOMMENDED                                 | -->
<!-- =================================================================================== -->
<robot name="giraffe_robot">
  <!-- World link -->
  <link name="world"/>
  <!-- Robot mounted to ceiling -->
  <joint name="world_joint" type="fixed">
    <parent link="world"/>
    <child link="base_link"/>
    <origin rpy="0.0 0.0 0.0" xyz="2.5 6.0 4.0"/>
  </joint>
  <!-- Base link - ceiling mount -->
  <link name="base_link">
    <visual>
      <geometry>
        <cylinder length="0.2" radius="0.1"/>
      </geometry>
      <material name="base_color">
        <color rgba="0.8 0.8 0.8 1.0"/>
      </material>
    </visual>
    <collision>
      <geometry>
        <cylinder length="0.2" radius="0.1"/>
      </geometry>
    </collision>
    <inertial>
      <mass value="5.0"/>
      <origin rpy="0 0 0" xyz="0.0 0.0 0.0"/>
      <inertia ixx="0.02916666666666667" ixy="0" ixz="0" iyy="0.02916666666666667" iyz="0" izz="0.025"/>
    </inertial>
  </link>
  <!-- Joint 1: First rotation of spherical joint (around Z-axis) -->
  <joint name="base_rotation_z" type="revolute">
    <parent link="base_link"/>
    <child link="shoulder_link"/>
    <origin rpy="0.0 0.0 0.0" xyz="0.0 0.0 -0.1"/>
    <axis xyz="0 0 1"/>
    <limit effort="100.0" lower="-3.14159265" upper="3.14159265" velocity="2.0"/>
    <dynamics damping="0.1" friction="0.0"/>
  </joint>
  <!-- Shoulder link -->
  <link name="shoulder_link">
    <visual>
      <geometry>
        <cylinder length="0.15" radius="0.08"/>
      </geometry>
      <material name="shoulder_color">
        <color rgba="0.7 0.7 0.7 1.0"/>
      </material>
    </visual>
    <collision>
      <geometry>
        <cylinder length="0.15" radius="0.08"/>
      </geometry>
    </collision>
    <inertial>
      <mass value="3.0"/>
      <origin rpy="0 0 0" xyz="0.0 0.0 0.0"/>
      <inertia ixx="0.010424999999999999" ixy="0" ixz="0" iyy="0.010424999999999999" iyz="0" izz="0.0096"/>
    </inertial>
  </link>
  <!-- Joint 2: Second rotation of spherical joint (around Y-axis) -->
  <joint name="shoulder_tilt_y" type="revolute">
    <parent link="shoulder_link"/>
    <child link="upper_arm_link"/>
    <origin rpy="0.0 0.0 0.0" xyz="0.0 0.0 -0.075"/>
    <axis xyz="0 1 0"/>
    <limit effort="100.0" lower="-1.57079633" upper="1.57079633" velocity="2.0"/>
    <dynamics damping="0.1" friction="0.0"/>
  </joint>
  <!-- Upper arm link -->
  <link name="upper_arm_link">
    <visual>
      <geometry>
        <box size="0.12 0.12 0.8"/>
      </geometry>
      <material name="upper_arm_color">
        <color rgba="0.6 0.6 0.6 1.0"/>
      </material>
    </visual>
    <collision>
      <geometry>
        <box size="0.12 0.12 0.8"/>
      </geometry>
    </collision>
    <inertial>
      <mass value="4.0"/>
      <origin rpy="0 0 0" xyz="0.0 0.0 0.0"/>
      <inertia ixx="0.21813333333333337" ixy="0" ixz="0" iyy="0.21813333333333337" iyz="0" izz="0.0096"/>
    </inertial>
  </link>
  <!-- Joint 3: Prismatic joint for telescopic extension -->
  <joint name="telescopic_joint" type="prismatic">
    <parent link="upper_arm_link"/>
    <child link="telescopic_link"/>
    <origin rpy="0.0 0.0 0.0" xyz="0.0 0.0 -0.4"/>
    <axis xyz="0 0 -1"/>
    <limit effort="200.0" lower="0.0" upper="6.5" velocity="1.0"/>
    <dynamics damping="0.2" friction="0.0"/>
  </joint>
  <!-- Telescopic link -->
  <link name="telescopic_link">
    <visual>
      <geometry>
        <cylinder length="1.0" radius="0.06"/>
      </geometry>
      <material name="telescopic_color">
        <color rgba="0.9 0.7 0.2 1.0"/>
      </material>
    </visual>
    <collision>
      <geometry>
        <cylinder length="1.0" radius="0.06"/>
      </geometry>
    </collision>
    <inertial>
      <mass value="2.0"/>
      <origin rpy="0 0 0" xyz="0.0 0.0 0.0"/>
      <inertia ixx="0.16846666666666665" ixy="0" ixz="0" iyy="0.16846666666666665" iyz="0" izz="0.0036"/>
    </inertial>
  </link>
  <!-- Joint 4: Wrist rotation 1 (around Z-axis) -->
  <joint name="wrist_1_joint" type="revolute">
    <parent link="telescopic_link"/>
    <child link="wrist_1_link"/>
    <origin rpy="0.0 0.0 0.0" xyz="0.0 0.0 -0.5"/>
    <axis xyz="0 0 1"/>
    <limit effort="50.0" lower="-3.14159265" upper="3.14159265" velocity="3.0"/>
    <dynamics damping="0.05" friction="0.0"/>
  </joint>
  <!-- Wrist 1 link -->
  <link name="wrist_1_link">
    <visual>
      <geometry>
        <cylinder length="0.08" radius="0.035"/>
      </geometry>
      <material name="wrist_color">
        <color rgba="0.5 0.5 0.5 1.0"/>
      </material>
    </visual>
    <collision>
      <geometry>
        <cylinder length="0.08" radius="0.035"/>
      </geometry>
    </collision>
    <inertial>
      <mass value="1.0"/>
      <origin rpy="0 0 0" xyz="0.0 0.0 0.0"/>
      <inertia ixx="0.0008395833333333333" ixy="0" ixz="0" iyy="0.0008395833333333333" iyz="0" izz="0.0006125000000000001"/>
    </inertial>
  </link>
  <!-- Joint 5: Wrist rotation 2 (around Y-axis for pitch control) -->
  <joint name="wrist_2_joint" type="revolute">
    <parent link="wrist_1_link"/>
    <child link="wrist_2_link"/>
    <origin rpy="0.0 0.0 0.0" xyz="0.0 0.0 -0.04"/>
    <axis xyz="0 1 0"/>
    <limit effort="50.0" lower="-2.61799388" upper="2.61799388" velocity="3.0"/>
    <dynamics damping="0.05" friction="0.0"/>
  </joint>
  <!-- Wrist 2 link -->
  <link name="wrist_2_link">
    <visual>
      <geometry>
        <cylinder length="0.06" radius="0.03"/>
      </geometry>
      <material name="wrist_color">
        <color rgba="0.5 0.5 0.5 1.0"/>
      </material>
    </visual>
    <collision>
      <geometry>
        <cylinder length="0.06" radius="0.03"/>
      </geometry>
    </collision>
    <inertial>
      <mass value="0.5"/>
      <origin rpy="0 0 0" xyz="0.0 0.0 0.0"/>
      <inertia ixx="0.0002625" ixy="0" ixz="0" iyy="0.0002625" iyz="0" izz="0.000225"/>
    </inertial>
  </link>
  <!-- End-effector joint (fixed) -->
  <joint name="ee_joint" type="fixed">
    <parent link="wrist_2_link"/>
    <child link="ee_link"/>
    <origin rpy="0.0 0.0 0.0" xyz="0.0 0.0 -0.03"/>
  </joint>
  <!-- End-effector link (microphone) -->
  <link name="ee_link">
    <visual>
      <geometry>
        <cylinder length="0.1" radius="0.02"/>
      </geometry>
      <material name="microphone_color">
        <color rgba="0.2 0.2 0.2 1.0"/>
      </material>
    </visual>
    <collision>
      <geometry>
        <cylinder length="0.1" radius="0.02"/>
      </geometry>
    </collision>
    <inertial>
      <mass value="0.2"/>
      <origin rpy="0 0 0" xyz="0.0 0.0 0.0"/>
      <inertia ixx="0.0001866666666666667" ixy="0" ixz="0" iyy="0.0001866666666666667" iyz="0" izz="4e-05"/>
    </inertial>
  </link>
</robot>
